<?xml version="1.0" ?>
<!-- =================================================================================== -->
<!-- |    This document was autogenerated by xacro from /home/leus/ros/indigo/src/rtm-ros-robotics/rtmros_tutorials/hrpsys_ros_bridge_tutorials/models//JAXON.urdf.xacro | -->
<!-- |    EDITING THIS FILE BY HAND IS NOT RECOMMENDED                                 | -->
<!-- =================================================================================== -->
<robot name="JAXON" xmlns:xacro="http://ros.org/wiki/xacro" xmlns:xi="http://www.w3.org/2001/XInclude">
  <link name="BODY">
    <visual>
      <origin rpy="0 -0 0" xyz="0 0 1.0185"/>
      <geometry>
	<mesh filename="package://hrpsys_ros_bridge_tutorials/models/JAXON_meshes/BODY_mesh.dae" scale="1 1 1"/>
      </geometry>
    </visual>
    <collision>
      <origin rpy="0 -0 0" xyz="0 0 1.0185"/>
      <geometry>
	<mesh filename="package://hrpsys_ros_bridge_tutorials/models/JAXON_meshes/BODY_mesh.dae" scale="1 1 1"/>
      </geometry>
    </collision>
    <inertial>
      <mass value="22.7"/>
      <origin rpy="0 -0 0" xyz="-0.1059 -0.00067 -0.023"/>
      <inertia ixx="0.229835" ixy="0.00171" ixz="0.135708" iyy="0.535336" iyz="0.000616" izz="0.549159"/>
    </inertial>
  </link>
  <gazebo reference="BODY">
    <mu1>0.9</mu1>
    <mu2>0.9</mu2>
  </gazebo>
  <link name="CHEST_LINK0">
    <visual>
      <origin rpy="0 -0 0" xyz="0.006 0 0.128"/>
      <geometry>
	<mesh filename="package://hrpsys_ros_bridge_tutorials/models/JAXON_meshes/CHEST_LINK0_mesh.dae" scale="1 1 1"/>
      </geometry>
    </visual>
    <collision>
      <origin rpy="0 -0 0" xyz="0.006 0 0.128"/>
      <geometry>
	<mesh filename="package://hrpsys_ros_bridge_tutorials/models/JAXON_meshes/CHEST_LINK0_mesh.dae" scale="1 1 1"/>
      </geometry>
    </collision>
    <inertial>
      <mass value="0.866"/>
      <origin rpy="0 -0 0" xyz="-0.0084 0.00137 0.01359"/>
      <inertia ixx="0.00125384" ixy="0" ixz="0" iyy="0.00123407" iyz="0" izz="0.000677392"/>
    </inertial>
  </link>
  <gazebo reference="CHEST_LINK0">
    <mu1>0.9</mu1>
    <mu2>0.9</mu2>
  </gazebo>
  <link name="CHEST_LINK1">
    <visual>
      <origin rpy="0 -0 0" xyz="0 0 0.025"/>
      <geometry>
	<mesh filename="package://hrpsys_ros_bridge_tutorials/models/JAXON_meshes/CHEST_LINK1_mesh.dae" scale="1 1 1"/>
      </geometry>
    </visual>
    <collision>
      <origin rpy="0 -0 0" xyz="0 0 0.025"/>
      <geometry>
	<mesh filename="package://hrpsys_ros_bridge_tutorials/models/JAXON_meshes/CHEST_LINK1_mesh.dae" scale="1 1 1"/>
      </geometry>
    </collision>
    <inertial>
      <mass value="18.23"/>
      <origin rpy="0 -0 0" xyz="-0.111697 0.0039 0.03652"/>
      <inertia ixx="0.186526" ixy="0.003889" ixz="-0.039414" iyy="0.418012" iyz="0.001281" izz="0.477668"/>
    </inertial>
  </link>
  <gazebo reference="CHEST_LINK1">
    <mu1>0.9</mu1>
    <mu2>0.9</mu2>
  </gazebo>
  <link name="CHEST_LINK2">
    <visual>
      <origin rpy="0 -0 0" xyz="0 0 0.3085"/>
      <geometry>
	<mesh filename="package://hrpsys_ros_bridge_tutorials/models/JAXON_meshes/CHEST_LINK2_mesh.dae" scale="1 1 1"/>
      </geometry>
    </visual>
    <collision>
      <origin rpy="0 -0 0" xyz="0 0 0.3085"/>
      <geometry>
	<mesh filename="package://hrpsys_ros_bridge_tutorials/models/JAXON_meshes/CHEST_LINK2_mesh.dae" scale="1 1 1"/>
      </geometry>
    </collision>
    <inertial>
      <mass value="31.33"/>
      <origin rpy="0 -0 0" xyz="-0.13693 -0.00113 -0.05796"/>
      <inertia ixx="0.510746" ixy="0.005161" ixz="0.143334" iyy="1.09582" iyz="0.004687" izz="1.02505"/>
    </inertial>
  </link>
  <gazebo reference="CHEST_LINK2">
    <mu1>0.9</mu1>
    <mu2>0.9</mu2>
  </gazebo>
  <link name="HEAD_LINK0">
    <visual>
      <origin rpy="0 -0 0" xyz="-0.015 0 0.0835"/>
      <geometry>
	<mesh filename="package://hrpsys_ros_bridge_tutorials/models/JAXON_meshes/HEAD_LINK0_mesh.dae" scale="1 1 1"/>
      </geometry>
    </visual>
    <collision>
      <origin rpy="0 -0 0" xyz="-0.015 0 0.0835"/>
      <geometry>
	<mesh filename="package://hrpsys_ros_bridge_tutorials/models/JAXON_meshes/HEAD_LINK0_mesh.dae" scale="1 1 1"/>
      </geometry>
    </collision>
    <inertial>
      <mass value="1.086"/>
      <origin rpy="0 -0 0" xyz="-0.01227 3e-05 0.03231"/>
      <inertia ixx="0.0031" ixy="0" ixz="0" iyy="0.0035" iyz="0" izz="0.00119"/>
    </inertial>
  </link>
  <gazebo reference="HEAD_LINK0">
    <mu1>0.9</mu1>
    <mu2>0.9</mu2>
  </gazebo>
  <link name="HEAD_LINK1">
    <visual>
      <origin rpy="0 -0 0" xyz="0 0 0.102"/>
      <geometry>
	<mesh filename="package://hrpsys_ros_bridge_tutorials/models/JAXON_meshes/HEAD_LINK1_mesh.dae" scale="1 1 1"/>
      </geometry>
    </visual>
    <collision>
      <origin rpy="0 -0 0" xyz="0 0 0.102"/>
      <geometry>
	<mesh filename="package://hrpsys_ros_bridge_tutorials/models/JAXON_meshes/HEAD_LINK1_mesh.dae" scale="1 1 1"/>
      </geometry>
    </collision>
    <inertial>
      <mass value="4.274"/>
      <origin rpy="0 -0 0" xyz="0.042 0.004 0.058"/>
      <inertia ixx="0.035683" ixy="0.000877" ixz="-0.003172" iyy="0.040037" iyz="0.000652" izz="0.035345"/>
    </inertial>
  </link>
  <gazebo reference="HEAD_LINK1">
    <mu1>0.9</mu1>
    <mu2>0.9</mu2>
  </gazebo>
  <link name="LARM_LINK0">
    <visual>
      <origin rpy="0 -0 0" xyz="0 0.0875 0"/>
      <geometry>
	<mesh filename="package://hrpsys_ros_bridge_tutorials/models/JAXON_meshes/LARM_LINK0_mesh.dae" scale="1 1 1"/>
      </geometry>
    </visual>
    <collision>
      <origin rpy="0 -0 0" xyz="0 0.0875 0"/>
      <geometry>
	<mesh filename="package://hrpsys_ros_bridge_tutorials/models/JAXON_meshes/LARM_LINK0_mesh.dae" scale="1 1 1"/>
      </geometry>
    </collision>
    <inertial>
      <mass value="1.048"/>
      <origin rpy="0 -0 0" xyz="-0.01745 0.00887 -0.00015"/>
      <inertia ixx="0.0029762" ixy="0" ixz="0" iyy="0.00235085" iyz="0" izz="0.00355486"/>
    </inertial>
  </link>
  <gazebo reference="LARM_LINK0">
    <mu1>0.9</mu1>
    <mu2>0.9</mu2>
  </gazebo>
  <link name="LARM_LINK1">
    <visual>
      <origin rpy="0 -0 0" xyz="0 0.07275 0"/>
      <geometry>
	<mesh filename="package://hrpsys_ros_bridge_tutorials/models/JAXON_meshes/LARM_LINK1_mesh.dae" scale="1 1 1"/>
      </geometry>
    </visual>
    <collision>
      <origin rpy="0 -0 0" xyz="0 0.07275 0"/>
      <geometry>
	<mesh filename="package://hrpsys_ros_bridge_tutorials/models/JAXON_meshes/LARM_LINK1_mesh.dae" scale="1 1 1"/>
      </geometry>
    </collision>
    <inertial>
      <mass value="0.298"/>
      <origin rpy="0 -0 0" xyz="0.00011 0.01799 0.00288"/>
      <inertia ixx="0.000412035" ixy="0" ixz="0" iyy="0.000251611" iyz="0" izz="0.000376771"/>
    </inertial>
  </link>
  <gazebo reference="LARM_LINK1">
    <mu1>0.9</mu1>
    <mu2>0.9</mu2>
  </gazebo>
  <link name="LARM_LINK2">
    <visual>
      <origin rpy="0 -0 0" xyz="0 0.057 0"/>
      <geometry>
	<mesh filename="package://hrpsys_ros_bridge_tutorials/models/JAXON_meshes/LARM_LINK2_mesh.dae" scale="1 1 1"/>
      </geometry>
    </visual>
    <collision>
      <origin rpy="0 -0 0" xyz="0 0.057 0"/>
      <geometry>
	<mesh filename="package://hrpsys_ros_bridge_tutorials/models/JAXON_meshes/LARM_LINK2_mesh.dae" scale="1 1 1"/>
      </geometry>
    </collision>
    <inertial>
      <mass value="2.168"/>
      <origin rpy="0 -0 0" xyz="0.00845 0.00671 -0.0881"/>
      <inertia ixx="0.0127408" ixy="0" ixz="0" iyy="0.0133751" iyz="0" izz="0.00460362"/>
    </inertial>
  </link>
  <gazebo reference="LARM_LINK2">
    <mu1>0.9</mu1>
    <mu2>0.9</mu2>
  </gazebo>
  <link name="LARM_LINK3">
    <visual>
      <origin rpy="0 -0 0" xyz="0 0 -0.1965"/>
      <geometry>
	<mesh filename="package://hrpsys_ros_bridge_tutorials/models/JAXON_meshes/LARM_LINK3_mesh.dae" scale="1 1 1"/>
      </geometry>
    </visual>
    <collision>
      <origin rpy="0 -0 0" xyz="0 0 -0.1965"/>
      <geometry>
	<mesh filename="package://hrpsys_ros_bridge_tutorials/models/JAXON_meshes/LARM_LINK3_mesh.dae" scale="1 1 1"/>
      </geometry>
    </collision>
    <inertial>
      <mass value="1.315"/>
      <origin rpy="0 -0 0" xyz="0.01393 4e-05 -0.07574"/>
      <inertia ixx="0.00451716" ixy="0" ixz="0" iyy="0.0055237" iyz="0" izz="0.00217053"/>
    </inertial>
  </link>
  <gazebo reference="LARM_LINK3">
    <mu1>0.9</mu1>
    <mu2>0.9</mu2>
  </gazebo>
  <link name="LARM_LINK4">
    <visual>
      <origin rpy="0 -0 0" xyz="0 0 -0.126"/>
      <geometry>
	<mesh filename="package://hrpsys_ros_bridge_tutorials/models/JAXON_meshes/LARM_LINK4_mesh.dae" scale="1 1 1"/>
      </geometry>
    </visual>
    <collision>
      <origin rpy="0 -0 0" xyz="0 0 -0.126"/>
      <geometry>
	<mesh filename="package://hrpsys_ros_bridge_tutorials/models/JAXON_meshes/LARM_LINK4_mesh.dae" scale="1 1 1"/>
      </geometry>
    </collision>
    <inertial>
      <mass value="1.641"/>
      <origin rpy="0 -0 0" xyz="3e-05 0.00551 -0.0426"/>
      <inertia ixx="0.00665559" ixy="0" ixz="0" iyy="0.00598857" iyz="0" izz="0.00288237"/>
    </inertial>
  </link>
  <gazebo reference="LARM_LINK4">
    <mu1>0.9</mu1>
    <mu2>0.9</mu2>
  </gazebo>
  <link name="LARM_LINK5">
    <visual>
      <origin rpy="0 -0 0" xyz="0 0 -0.1275"/>
      <geometry>
	<mesh filename="package://hrpsys_ros_bridge_tutorials/models/JAXON_meshes/LARM_LINK5_mesh.dae" scale="1 1 1"/>
      </geometry>
    </visual>
    <collision>
      <origin rpy="0 -0 0" xyz="0 0 -0.1275"/>
      <geometry>
	<mesh filename="package://hrpsys_ros_bridge_tutorials/models/JAXON_meshes/LARM_LINK5_mesh.dae" scale="1 1 1"/>
      </geometry>
    </collision>
    <inertial>
      <mass value="1.305"/>
      <origin rpy="0 -0 0" xyz="0.01271 2e-05 -0.08415"/>
      <inertia ixx="0.00533939" ixy="0" ixz="0" iyy="0.00624028" iyz="0" izz="0.00205604"/>
    </inertial>
  </link>
  <gazebo reference="LARM_LINK5">
    <mu1>0.9</mu1>
    <mu2>0.9</mu2>
  </gazebo>
  <link name="LARM_LINK6">
    <visual>
      <origin rpy="0 -0 0" xyz="0 0 -0.146"/>
      <geometry>
	<mesh filename="package://hrpsys_ros_bridge_tutorials/models/JAXON_meshes/LARM_LINK6_mesh.dae" scale="1 1 1"/>
      </geometry>
    </visual>
    <collision>
      <origin rpy="0 -0 0" xyz="0 0 -0.146"/>
      <geometry>
	<mesh filename="package://hrpsys_ros_bridge_tutorials/models/JAXON_meshes/LARM_LINK6_mesh.dae" scale="1 1 1"/>
      </geometry>
    </collision>
    <inertial>
      <mass value="0.505"/>
      <origin rpy="0 -0 0" xyz="0.00013 0.01427 0.00188"/>
      <inertia ixx="0.000901789" ixy="0" ixz="0" iyy="0.000626727" iyz="0" izz="0.000593753"/>
    </inertial>
  </link>
  <gazebo reference="LARM_LINK6">
    <mu1>0.9</mu1>
    <mu2>0.9</mu2>
  </gazebo>
  <link name="RARM_LINK0">
    <visual>
      <origin rpy="0 -0 0" xyz="0 -0.0875 0"/>
      <geometry>
	<mesh filename="package://hrpsys_ros_bridge_tutorials/models/JAXON_meshes/RARM_LINK0_mesh.dae" scale="1 1 1"/>
      </geometry>
    </visual>
    <collision>
      <origin rpy="0 -0 0" xyz="0 -0.0875 0"/>
      <geometry>
	<mesh filename="package://hrpsys_ros_bridge_tutorials/models/JAXON_meshes/RARM_LINK0_mesh.dae" scale="1 1 1"/>
      </geometry>
    </collision>
    <inertial>
      <mass value="1.048"/>
      <origin rpy="0 -0 0" xyz="-0.01745 -0.00887 -0.00015"/>
      <inertia ixx="0.0029762" ixy="0" ixz="0" iyy="0.00235085" iyz="0" izz="0.00355486"/>
    </inertial>
  </link>
  <gazebo reference="RARM_LINK0">
    <mu1>0.9</mu1>
    <mu2>0.9</mu2>
  </gazebo>
  <link name="RARM_LINK1">
    <visual>
      <origin rpy="0 -0 0" xyz="0 -0.07275 0"/>
      <geometry>
	<mesh filename="package://hrpsys_ros_bridge_tutorials/models/JAXON_meshes/RARM_LINK1_mesh.dae" scale="1 1 1"/>
      </geometry>
    </visual>
    <collision>
      <origin rpy="0 -0 0" xyz="0 -0.07275 0"/>
      <geometry>
	<mesh filename="package://hrpsys_ros_bridge_tutorials/models/JAXON_meshes/RARM_LINK1_mesh.dae" scale="1 1 1"/>
      </geometry>
    </collision>
    <inertial>
      <mass value="0.298"/>
      <origin rpy="0 -0 0" xyz="0.00011 -0.01799 0.00288"/>
      <inertia ixx="0.000412035" ixy="0" ixz="0" iyy="0.000251611" iyz="0" izz="0.000376771"/>
    </inertial>
  </link>
  <gazebo reference="RARM_LINK1">
    <mu1>0.9</mu1>
    <mu2>0.9</mu2>
  </gazebo>
  <link name="RARM_LINK2">
    <visual>
      <origin rpy="0 -0 0" xyz="0 -0.057 0"/>
      <geometry>
	<mesh filename="package://hrpsys_ros_bridge_tutorials/models/JAXON_meshes/RARM_LINK2_mesh.dae" scale="1 1 1"/>
      </geometry>
    </visual>
    <collision>
      <origin rpy="0 -0 0" xyz="0 -0.057 0"/>
      <geometry>
	<mesh filename="package://hrpsys_ros_bridge_tutorials/models/JAXON_meshes/RARM_LINK2_mesh.dae" scale="1 1 1"/>
      </geometry>
    </collision>
    <inertial>
      <mass value="2.168"/>
      <origin rpy="0 -0 0" xyz="0.00845 -0.00671 -0.0881"/>
      <inertia ixx="0.0127408" ixy="0" ixz="0" iyy="0.0133751" iyz="0" izz="0.00460362"/>
    </inertial>
  </link>
  <gazebo reference="RARM_LINK2">
    <mu1>0.9</mu1>
    <mu2>0.9</mu2>
  </gazebo>
  <link name="RARM_LINK3">
    <visual>
      <origin rpy="0 -0 0" xyz="0 0 -0.1965"/>
      <geometry>
	<mesh filename="package://hrpsys_ros_bridge_tutorials/models/JAXON_meshes/RARM_LINK3_mesh.dae" scale="1 1 1"/>
      </geometry>
    </visual>
    <collision>
      <origin rpy="0 -0 0" xyz="0 0 -0.1965"/>
      <geometry>
	<mesh filename="package://hrpsys_ros_bridge_tutorials/models/JAXON_meshes/RARM_LINK3_mesh.dae" scale="1 1 1"/>
      </geometry>
    </collision>
    <inertial>
      <mass value="1.315"/>
      <origin rpy="0 -0 0" xyz="0.01393 -4e-05 -0.07574"/>
      <inertia ixx="0.00451716" ixy="0" ixz="0" iyy="0.0055237" iyz="0" izz="0.00217053"/>
    </inertial>
  </link>
  <gazebo reference="RARM_LINK3">
    <mu1>0.9</mu1>
    <mu2>0.9</mu2>
  </gazebo>
  <link name="RARM_LINK4">
    <visual>
      <origin rpy="0 -0 0" xyz="0 0 -0.126"/>
      <geometry>
	<mesh filename="package://hrpsys_ros_bridge_tutorials/models/JAXON_meshes/RARM_LINK4_mesh.dae" scale="1 1 1"/>
      </geometry>
    </visual>
    <collision>
      <origin rpy="0 -0 0" xyz="0 0 -0.126"/>
      <geometry>
	<mesh filename="package://hrpsys_ros_bridge_tutorials/models/JAXON_meshes/RARM_LINK4_mesh.dae" scale="1 1 1"/>
      </geometry>
    </collision>
    <inertial>
      <mass value="1.641"/>
      <origin rpy="0 -0 0" xyz="3e-05 -0.00551 -0.0426"/>
      <inertia ixx="0.00665559" ixy="0" ixz="0" iyy="0.00598857" iyz="0" izz="0.00288237"/>
    </inertial>
  </link>
  <gazebo reference="RARM_LINK4">
    <mu1>0.9</mu1>
    <mu2>0.9</mu2>
  </gazebo>
  <link name="RARM_LINK5">
    <visual>
      <origin rpy="0 -0 0" xyz="0 0 -0.1275"/>
      <geometry>
	<mesh filename="package://hrpsys_ros_bridge_tutorials/models/JAXON_meshes/RARM_LINK5_mesh.dae" scale="1 1 1"/>
      </geometry>
    </visual>
    <collision>
      <origin rpy="0 -0 0" xyz="0 0 -0.1275"/>
      <geometry>
	<mesh filename="package://hrpsys_ros_bridge_tutorials/models/JAXON_meshes/RARM_LINK5_mesh.dae" scale="1 1 1"/>
      </geometry>
    </collision>
    <inertial>
      <mass value="1.305"/>
      <origin rpy="0 -0 0" xyz="0.01271 -2e-05 -0.08415"/>
      <inertia ixx="0.00533939" ixy="0" ixz="0" iyy="0.00624028" iyz="0" izz="0.00205604"/>
    </inertial>
  </link>
  <gazebo reference="RARM_LINK5">
    <mu1>0.9</mu1>
    <mu2>0.9</mu2>
  </gazebo>
  <link name="RARM_LINK6">
    <visual>
      <origin rpy="0 -0 0" xyz="0 0 -0.146"/>
      <geometry>
	<mesh filename="package://hrpsys_ros_bridge_tutorials/models/JAXON_meshes/RARM_LINK6_mesh.dae" scale="1 1 1"/>
      </geometry>
    </visual>
    <collision>
      <origin rpy="0 -0 0" xyz="0 0 -0.146"/>
      <geometry>
	<mesh filename="package://hrpsys_ros_bridge_tutorials/models/JAXON_meshes/RARM_LINK6_mesh.dae" scale="1 1 1"/>
      </geometry>
    </collision>
    <inertial>
      <mass value="0.505"/>
      <origin rpy="0 -0 0" xyz="0.00013 -0.01427 0.00188"/>
      <inertia ixx="0.000901789" ixy="0" ixz="0" iyy="0.000626727" iyz="0" izz="0.000593753"/>
    </inertial>
  </link>
  <gazebo reference="RARM_LINK6">
    <mu1>0.9</mu1>
    <mu2>0.9</mu2>
  </gazebo>
  <link name="LLEG_LINK0">
    <visual>
      <origin rpy="0 -0 0" xyz="0 0.1 0.0095"/>
      <geometry>
	<mesh filename="package://hrpsys_ros_bridge_tutorials/models/JAXON_meshes/LLEG_LINK0_mesh.dae" scale="1 1 1"/>
      </geometry>
    </visual>
    <collision>
      <origin rpy="0 -0 0" xyz="0 0.1 0.0095"/>
      <geometry>
	<mesh filename="package://hrpsys_ros_bridge_tutorials/models/JAXON_meshes/LLEG_LINK0_mesh.dae" scale="1 1 1"/>
      </geometry>
    </collision>
    <inertial>
      <mass value="2.915"/>
      <origin rpy="0 -0 0" xyz="-0.02299 -0.00588 -0.07031"/>
      <inertia ixx="0.00999808" ixy="-1.99354e-06" ixz="7.22147e-07" iyy="0.00999559" iyz="3.13302e-06" izz="0.00999172"/>
    </inertial>
  </link>
  <gazebo reference="LLEG_LINK0">
    <mu1>0.9</mu1>
    <mu2>0.9</mu2>
  </gazebo>
  <link name="LLEG_LINK1">
    <visual>
      <origin rpy="0 -0 0" xyz="0 0 -0.122"/>
      <geometry>
	<mesh filename="package://hrpsys_ros_bridge_tutorials/models/JAXON_meshes/LLEG_LINK1_mesh.dae" scale="1 1 1"/>
      </geometry>
    </visual>
    <collision>
      <origin rpy="0 -0 0" xyz="0 0 -0.122"/>
      <geometry>
	<mesh filename="package://hrpsys_ros_bridge_tutorials/models/JAXON_meshes/LLEG_LINK1_mesh.dae" scale="1 1 1"/>
      </geometry>
    </collision>
    <inertial>
      <mass value="1.199"/>
      <origin rpy="0 -0 0" xyz="-0.00441 0.00696 -0.00694"/>
      <inertia ixx="0.00299879" ixy="-3.30504e-37" ixz="9.70868e-20" iyy="0.00179963" iyz="4.51014e-37" izz="0.00343603"/>
    </inertial>
  </link>
  <gazebo reference="LLEG_LINK1">
    <mu1>0.9</mu1>
    <mu2>0.9</mu2>
  </gazebo>
  <link name="LLEG_LINK2">
    <visual>
      <origin rpy="0 -0 0" xyz="0 0 -0.01"/>
      <geometry>
	<mesh filename="package://hrpsys_ros_bridge_tutorials/models/JAXON_meshes/LLEG_LINK2_mesh.dae" scale="1 1 1"/>
      </geometry>
    </visual>
    <collision>
      <origin rpy="0 -0 0" xyz="0 0 -0.01"/>
      <geometry>
	<mesh filename="package://hrpsys_ros_bridge_tutorials/models/JAXON_meshes/LLEG_LINK2_mesh.dae" scale="1 1 1"/>
      </geometry>
    </collision>
    <inertial>
      <mass value="5.783"/>
      <origin rpy="0 -0 0" xyz="0.00658 0.03431 -0.18864"/>
      <inertia ixx="0.109779" ixy="0.0002015" ixz="0.00500356" iyy="0.109973" iyz="-0.00331032" izz="0.0103577"/>
    </inertial>
  </link>
  <gazebo reference="LLEG_LINK2">
    <mu1>0.9</mu1>
    <mu2>0.9</mu2>
  </gazebo>
  <link name="LLEG_LINK3">
    <visual>
      <origin rpy="0 -0 0" xyz="0 0 -0.38"/>
      <geometry>
	<mesh filename="package://hrpsys_ros_bridge_tutorials/models/JAXON_meshes/LLEG_LINK3_mesh.dae" scale="1 1 1"/>
      </geometry>
    </visual>
    <collision>
      <origin rpy="0 -0 0" xyz="0 0 -0.38"/>
      <geometry>
	<mesh filename="package://hrpsys_ros_bridge_tutorials/models/JAXON_meshes/LLEG_LINK3_mesh.dae" scale="1 1 1"/>
      </geometry>
    </collision>
    <inertial>
      <mass value="3.156"/>
      <origin rpy="0 -0 0" xyz="0.0176 0.01611 -0.17992"/>
      <inertia ixx="0.0592962" ixy="0" ixz="0" iyy="0.0592638" iyz="0" izz="0.00799027"/>
    </inertial>
  </link>
  <gazebo reference="LLEG_LINK3">
    <mu1>0.9</mu1>
    <mu2>0.9</mu2>
  </gazebo>
  <link name="LLEG_LINK4">
    <visual>
      <origin rpy="0 -0 0" xyz="0 0 -0.38"/>
      <geometry>
	<mesh filename="package://hrpsys_ros_bridge_tutorials/models/JAXON_meshes/LLEG_LINK4_mesh.dae" scale="1 1 1"/>
      </geometry>
    </visual>
    <collision>
      <origin rpy="0 -0 0" xyz="0 0 -0.38"/>
      <geometry>
	<mesh filename="package://hrpsys_ros_bridge_tutorials/models/JAXON_meshes/LLEG_LINK4_mesh.dae" scale="1 1 1"/>
      </geometry>
    </collision>
    <inertial>
      <mass value="0.836"/>
      <origin rpy="0 -0 0" xyz="-0.00769 0.00203 -0.00714"/>
      <inertia ixx="0.0014428" ixy="0" ixz="0" iyy="0.001606" iyz="0" izz="0.00150135"/>
    </inertial>
  </link>
  <gazebo reference="LLEG_LINK4">
    <mu1>0.9</mu1>
    <mu2>0.9</mu2>
  </gazebo>
  <link name="LLEG_LINK5">
    <visual>
      <origin rpy="0 -0 0" xyz="0 0 -0.04"/>
      <geometry>
	<mesh filename="package://hrpsys_ros_bridge_tutorials/models/JAXON_meshes/LLEG_LINK5_mesh.dae" scale="1 1 1"/>
      </geometry>
    </visual>
    <inertial>
      <mass value="1.552"/>
      <origin rpy="0 -0 0" xyz="0.00064 0.00264 -0.05633"/>
      <inertia ixx="0.00442296" ixy="0" ixz="0" iyy="0.00907896" iyz="0" izz="0.00902826"/>
    </inertial>
    <collision>
      <origin rpy="0 -0 0" xyz="0.015 0.010 -0.08"/>
      <geometry>
	<box size="0.240 0.138 0.01"/>
      </geometry>
    </collision>
  </link>
  <link name="RLEG_LINK0">
    <visual>
      <origin rpy="0 -0 0" xyz="0 -0.1 0.0095"/>
      <geometry>
	<mesh filename="package://hrpsys_ros_bridge_tutorials/models/JAXON_meshes/RLEG_LINK0_mesh.dae" scale="1 1 1"/>
      </geometry>
    </visual>
    <collision>
      <origin rpy="0 -0 0" xyz="0 -0.1 0.0095"/>
      <geometry>
	<mesh filename="package://hrpsys_ros_bridge_tutorials/models/JAXON_meshes/RLEG_LINK0_mesh.dae" scale="1 1 1"/>
      </geometry>
    </collision>
    <inertial>
      <mass value="2.915"/>
      <origin rpy="0 -0 0" xyz="-0.02299 0.00588 -0.07031"/>
      <inertia ixx="0.00999808" ixy="-1.99354e-06" ixz="-7.22147e-07" iyy="0.00999559" iyz="-3.13302e-06" izz="0.00999172"/>
    </inertial>
  </link>
  <gazebo reference="RLEG_LINK0">
    <mu1>0.9</mu1>
    <mu2>0.9</mu2>
  </gazebo>
  <link name="RLEG_LINK1">
    <visual>
      <origin rpy="0 -0 0" xyz="0 0 -0.122"/>
      <geometry>
	<mesh filename="package://hrpsys_ros_bridge_tutorials/models/JAXON_meshes/RLEG_LINK1_mesh.dae" scale="1 1 1"/>
      </geometry>
    </visual>
    <collision>
      <origin rpy="0 -0 0" xyz="0 0 -0.122"/>
      <geometry>
	<mesh filename="package://hrpsys_ros_bridge_tutorials/models/JAXON_meshes/RLEG_LINK1_mesh.dae" scale="1 1 1"/>
      </geometry>
    </collision>
    <inertial>
      <mass value="1.199"/>
      <origin rpy="0 -0 0" xyz="-0.00441 -0.00696 -0.00694"/>
      <inertia ixx="0.00299879" ixy="3.30504e-37" ixz="9.70868e-20" iyy="0.00179963" iyz="-4.51014e-37" izz="0.00343603"/>
    </inertial>
  </link>
  <gazebo reference="RLEG_LINK1">
    <mu1>0.9</mu1>
    <mu2>0.9</mu2>
  </gazebo>
  <link name="RLEG_LINK2">
    <visual>
      <origin rpy="0 -0 0" xyz="0 0 -0.01"/>
      <geometry>
	<mesh filename="package://hrpsys_ros_bridge_tutorials/models/JAXON_meshes/RLEG_LINK2_mesh.dae" scale="1 1 1"/>
      </geometry>
    </visual>
    <collision>
      <origin rpy="0 -0 0" xyz="0 0 -0.01"/>
      <geometry>
	<mesh filename="package://hrpsys_ros_bridge_tutorials/models/JAXON_meshes/RLEG_LINK2_mesh.dae" scale="1 1 1"/>
      </geometry>
    </collision>
    <inertial>
      <mass value="5.783"/>
      <origin rpy="0 -0 0" xyz="0.00658 -0.03431 -0.18864"/>
      <inertia ixx="0.109779" ixy="-0.0002015" ixz="0.00500356" iyy="0.109973" iyz="0.00331032" izz="0.0103577"/>
    </inertial>
  </link>
  <gazebo reference="RLEG_LINK2">
    <mu1>0.9</mu1>
    <mu2>0.9</mu2>
  </gazebo>
  <link name="RLEG_LINK3">
    <visual>
      <origin rpy="0 -0 0" xyz="0 0 -0.38"/>
      <geometry>
	<mesh filename="package://hrpsys_ros_bridge_tutorials/models/JAXON_meshes/RLEG_LINK3_mesh.dae" scale="1 1 1"/>
      </geometry>
    </visual>
    <collision>
      <origin rpy="0 -0 0" xyz="0 0 -0.38"/>
      <geometry>
	<mesh filename="package://hrpsys_ros_bridge_tutorials/models/JAXON_meshes/RLEG_LINK3_mesh.dae" scale="1 1 1"/>
      </geometry>
    </collision>
    <inertial>
      <mass value="3.156"/>
      <origin rpy="0 -0 0" xyz="0.0176 -0.01611 -0.17992"/>
      <inertia ixx="0.0592962" ixy="0" ixz="0" iyy="0.0592638" iyz="0" izz="0.00799027"/>
    </inertial>
  </link>
  <gazebo reference="RLEG_LINK3">
    <mu1>0.9</mu1>
    <mu2>0.9</mu2>
  </gazebo>
  <link name="RLEG_LINK4">
    <visual>
      <origin rpy="0 -0 0" xyz="0 0 -0.38"/>
      <geometry>
	<mesh filename="package://hrpsys_ros_bridge_tutorials/models/JAXON_meshes/RLEG_LINK4_mesh.dae" scale="1 1 1"/>
      </geometry>
    </visual>
    <collision>
      <origin rpy="0 -0 0" xyz="0 0 -0.38"/>
      <geometry>
	<mesh filename="package://hrpsys_ros_bridge_tutorials/models/JAXON_meshes/RLEG_LINK4_mesh.dae" scale="1 1 1"/>
      </geometry>
    </collision>
    <inertial>
      <mass value="0.836"/>
      <origin rpy="0 -0 0" xyz="-0.00769 -0.00203 -0.00714"/>
      <inertia ixx="0.0014428" ixy="0" ixz="0" iyy="0.001606" iyz="0" izz="0.00150135"/>
    </inertial>
  </link>
  <gazebo reference="RLEG_LINK4">
    <mu1>0.9</mu1>
    <mu2>0.9</mu2>
  </gazebo>
  <link name="RLEG_LINK5">
    <visual>
      <origin rpy="0 -0 0" xyz="0 0 -0.04"/>
      <geometry>
	<mesh filename="package://hrpsys_ros_bridge_tutorials/models/JAXON_meshes/RLEG_LINK5_mesh.dae" scale="1 1 1"/>
      </geometry>
    </visual>
    <inertial>
      <mass value="1.552"/>
      <origin rpy="0 -0 0" xyz="0.00064 -0.00264 -0.05633"/>
      <inertia ixx="0.00442296" ixy="0" ixz="0" iyy="0.00907896" iyz="0" izz="0.00902826"/>
    </inertial>
    <collision>
      <origin rpy="0 -0 0" xyz="0.015 -0.010 -0.08"/>
      <geometry>
	<box size="0.240 0.138 0.01"/>
      </geometry>
    </collision>
  </link>
  <joint name="CHEST_JOINT0" type="revolute">
    <parent link="BODY"/>
    <child link="CHEST_LINK0"/>
    <origin rpy="0 -0 0 " xyz="0.006 0 0.128"/>
    <axis xyz="1 0 0"/>
    <limit effort="869.069" lower="-0.198551" upper="0.198551" velocity="4"/>
    <dynamics damping="0.2" friction="0"/>
  </joint>
  <transmission name="CHEST_JOINT0_trans" type="pr2_mechanism_model/SimpleTransmission">
    <actuator name="CHEST_JOINT0_motor"/>
    <joint name="CHEST_JOINT0"/>
    <mechanicalReduction>1</mechanicalReduction>
  </transmission>
  <gazebo reference="CHEST_JOINT0">
    <cfmDamping>0.4</cfmDamping>
  </gazebo>
  <joint name="CHEST_JOINT1" type="revolute">
    <parent link="CHEST_LINK0"/>
    <child link="CHEST_LINK1"/>
    <origin rpy="0 -0 0 " xyz="0 0 0.025"/>
    <axis xyz="0 1 0"/>
    <limit effort="869.069" lower="-0.0523599" upper="0.610865" velocity="4"/>
    <dynamics damping="0.2" friction="0"/>
  </joint>
  <transmission name="CHEST_JOINT1_trans" type="pr2_mechanism_model/SimpleTransmission">
    <actuator name="CHEST_JOINT1_motor"/>
    <joint name="CHEST_JOINT1"/>
    <mechanicalReduction>1</mechanicalReduction>
  </transmission>
  <gazebo reference="CHEST_JOINT1">
    <cfmDamping>0.4</cfmDamping>
  </gazebo>
  <joint name="CHEST_JOINT2" type="revolute">
    <parent link="CHEST_LINK1"/>
    <child link="CHEST_LINK2"/>
    <origin rpy="0 -0 0 " xyz="0 0 0.3085"/>
    <axis xyz="0 0 1"/>
    <limit effort="434.534" lower="-1.0566" upper="1.0566" velocity="4"/>
    <dynamics damping="0.2" friction="0"/>
  </joint>
  <transmission name="CHEST_JOINT2_trans" type="pr2_mechanism_model/SimpleTransmission">
    <actuator name="CHEST_JOINT2_motor"/>
    <joint name="CHEST_JOINT2"/>
    <mechanicalReduction>1</mechanicalReduction>
  </transmission>
  <gazebo reference="CHEST_JOINT2">
    <cfmDamping>0.4</cfmDamping>
  </gazebo>
  <joint name="HEAD_JOINT0" type="revolute">
    <parent link="CHEST_LINK2"/>
    <child link="HEAD_LINK0"/>
    <origin rpy="0 -0 0 " xyz="-0.015 0 0.0835"/>
    <axis xyz="0 0 1"/>
    <limit effort="287.171" lower="-0.392699" upper="0.392699" velocity="4"/>
    <dynamics damping="0.2" friction="0"/>
  </joint>
  <transmission name="HEAD_JOINT0_trans" type="pr2_mechanism_model/SimpleTransmission">
    <actuator name="HEAD_JOINT0_motor"/>
    <joint name="HEAD_JOINT0"/>
    <mechanicalReduction>1</mechanicalReduction>
  </transmission>
  <gazebo reference="HEAD_JOINT0">
    <cfmDamping>0.4</cfmDamping>
  </gazebo>
  <joint name="HEAD_JOINT1" type="revolute">
    <parent link="HEAD_LINK0"/>
    <child link="HEAD_LINK1"/>
    <origin rpy="0 -0 0 " xyz="0 0 0.102"/>
    <axis xyz="0 1 0"/>
    <limit effort="287.171" lower="-0.549779" upper="0.671952" velocity="4"/>
    <dynamics damping="0.2" friction="0"/>
  </joint>
  <transmission name="HEAD_JOINT1_trans" type="pr2_mechanism_model/SimpleTransmission">
    <actuator name="HEAD_JOINT1_motor"/>
    <joint name="HEAD_JOINT1"/>
    <mechanicalReduction>1</mechanicalReduction>
  </transmission>
  <gazebo reference="HEAD_JOINT1">
    <cfmDamping>0.4</cfmDamping>
  </gazebo>
  <joint name="LARM_JOINT0" type="revolute">
    <parent link="CHEST_LINK2"/>
    <child link="LARM_LINK0"/>
    <origin rpy="0 -0 0 " xyz="0 0.0875 0"/>
    <axis xyz="0 0 1"/>
    <limit effort="287.171" lower="-1.4208" upper="0.306849" velocity="4"/>
    <dynamics damping="0.2" friction="0"/>
  </joint>
  <transmission name="LARM_JOINT0_trans" type="pr2_mechanism_model/SimpleTransmission">
    <actuator name="LARM_JOINT0_motor"/>
    <joint name="LARM_JOINT0"/>
    <mechanicalReduction>1</mechanicalReduction>
  </transmission>
  <gazebo reference="LARM_JOINT0">
    <cfmDamping>0.4</cfmDamping>
  </gazebo>
  <joint name="LARM_JOINT1" type="revolute">
    <parent link="LARM_LINK0"/>
    <child link="LARM_LINK1"/>
    <origin rpy="0 -0 0 " xyz="0 0.07275 0"/>
    <axis xyz="0 1 0"/>
    <limit effort="287.171" lower="-3.14159" upper="3.14159" velocity="4"/>
    <dynamics damping="0.2" friction="0"/>
  </joint>
  <transmission name="LARM_JOINT1_trans" type="pr2_mechanism_model/SimpleTransmission">
    <actuator name="LARM_JOINT1_motor"/>
    <joint name="LARM_JOINT1"/>
    <mechanicalReduction>1</mechanicalReduction>
  </transmission>
  <gazebo reference="LARM_JOINT1">
    <cfmDamping>0.4</cfmDamping>
  </gazebo>
  <joint name="LARM_JOINT2" type="revolute">
    <parent link="LARM_LINK1"/>
    <child link="LARM_LINK2"/>
    <origin rpy="0 -0 0 " xyz="0 0.057 0"/>
    <axis xyz="1 0 0"/>
    <limit effort="287.171" lower="0.2762" upper="3.14159" velocity="4"/>
    <dynamics damping="0.2" friction="0"/>
  </joint>
  <transmission name="LARM_JOINT2_trans" type="pr2_mechanism_model/SimpleTransmission">
    <actuator name="LARM_JOINT2_motor"/>
    <joint name="LARM_JOINT2"/>
    <mechanicalReduction>1</mechanicalReduction>
  </transmission>
  <gazebo reference="LARM_JOINT2">
    <cfmDamping>0.4</cfmDamping>
  </gazebo>
  <joint name="LARM_JOINT3" type="revolute">
    <parent link="LARM_LINK2"/>
    <child link="LARM_LINK3"/>
    <origin rpy="0 -0 0 " xyz="0 0 -0.1965"/>
    <axis xyz="0 0 1"/>
    <limit effort="287.171" lower="-3.14159" upper="3.14159" velocity="4"/>
    <dynamics damping="0.2" friction="0"/>
  </joint>
  <transmission name="LARM_JOINT3_trans" type="pr2_mechanism_model/SimpleTransmission">
    <actuator name="LARM_JOINT3_motor"/>
    <joint name="LARM_JOINT3"/>
    <mechanicalReduction>1</mechanicalReduction>
  </transmission>
  <gazebo reference="LARM_JOINT3">
    <cfmDamping>0.4</cfmDamping>
  </gazebo>
  <joint name="LARM_JOINT4" type="revolute">
    <parent link="LARM_LINK3"/>
    <child link="LARM_LINK4"/>
    <origin rpy="0 -0 0 " xyz="0 0 -0.126"/>
    <axis xyz="0 1 0"/>
    <limit effort="287.171" lower="-2.19006" upper="1.0472" velocity="4"/>
    <dynamics damping="0.2" friction="0"/>
  </joint>
  <transmission name="LARM_JOINT4_trans" type="pr2_mechanism_model/SimpleTransmission">
    <actuator name="LARM_JOINT4_motor"/>
    <joint name="LARM_JOINT4"/>
    <mechanicalReduction>1</mechanicalReduction>
  </transmission>
  <gazebo reference="LARM_JOINT4">
    <cfmDamping>0.4</cfmDamping>
  </gazebo>
  <joint name="LARM_JOINT5" type="revolute">
    <parent link="LARM_LINK4"/>
    <child link="LARM_LINK5"/>
    <origin rpy="0 -0 0 " xyz="0 0 -0.1275"/>
    <axis xyz="0 0 1"/>
    <limit effort="287.171" lower="-3.14159" upper="3.14159" velocity="4"/>
    <dynamics damping="0.2" friction="0"/>
  </joint>
  <transmission name="LARM_JOINT5_trans" type="pr2_mechanism_model/SimpleTransmission">
    <actuator name="LARM_JOINT5_motor"/>
    <joint name="LARM_JOINT5"/>
    <mechanicalReduction>1</mechanicalReduction>
  </transmission>
  <gazebo reference="LARM_JOINT5">
    <cfmDamping>0.4</cfmDamping>
  </gazebo>
  <joint name="LARM_JOINT6" type="revolute">
    <parent link="LARM_LINK5"/>
    <child link="LARM_LINK6"/>
    <origin rpy="0 -0 0 " xyz="0 0 -0.146"/>
    <axis xyz="1 0 0"/>
    <limit effort="287.171" lower="-1.54494" upper="1.5708" velocity="4"/>
    <dynamics damping="0.2" friction="0"/>
  </joint>
  <transmission name="LARM_JOINT6_trans" type="pr2_mechanism_model/SimpleTransmission">
    <actuator name="LARM_JOINT6_motor"/>
    <joint name="LARM_JOINT6"/>
    <mechanicalReduction>1</mechanicalReduction>
  </transmission>
  <gazebo reference="LARM_JOINT6">
    <cfmDamping>0.4</cfmDamping>
  </gazebo>
  <joint name="LARM_JOINT7" type="revolute">
    <parent link="LARM_LINK6"/>
    <child link="LARM_LINK7"/>
    <origin rpy="0 -0 0 " xyz="0 0 -0.04"/>
    <axis xyz="0 1 0"/>
    <limit effort="288.965" lower="-1.41372" upper="1.0472" velocity="4"/>
    <dynamics damping="0.2" friction="0"/>
  </joint>
  <transmission name="LARM_JOINT7_trans" type="pr2_mechanism_model/SimpleTransmission">
    <actuator name="LARM_JOINT7_motor"/>
    <joint name="LARM_JOINT7"/>
    <mechanicalReduction>1</mechanicalReduction>
  </transmission>
  <gazebo reference="LARM_JOINT7">
    <cfmDamping>0.4</cfmDamping>
  </gazebo>
  <joint name="RARM_JOINT0" type="revolute">
    <parent link="CHEST_LINK2"/>
    <child link="RARM_LINK0"/>
    <origin rpy="0 -0 0 " xyz="0 -0.0875 0"/>
    <axis xyz="0 0 1"/>
    <limit effort="287.171" lower="-0.306849" upper="1.4208" velocity="4"/>
    <dynamics damping="0.2" friction="0"/>
  </joint>
  <transmission name="RARM_JOINT0_trans" type="pr2_mechanism_model/SimpleTransmission">
    <actuator name="RARM_JOINT0_motor"/>
    <joint name="RARM_JOINT0"/>
    <mechanicalReduction>1</mechanicalReduction>
  </transmission>
  <gazebo reference="RARM_JOINT0">
    <cfmDamping>0.4</cfmDamping>
  </gazebo>
  <joint name="RARM_JOINT1" type="revolute">
    <parent link="RARM_LINK0"/>
    <child link="RARM_LINK1"/>
    <origin rpy="0 -0 0 " xyz="0 -0.07275 0"/>
    <axis xyz="0 1 0"/>
    <limit effort="287.171" lower="-3.14159" upper="3.14159" velocity="4"/>
    <dynamics damping="0.2" friction="0"/>
  </joint>
  <transmission name="RARM_JOINT1_trans" type="pr2_mechanism_model/SimpleTransmission">
    <actuator name="RARM_JOINT1_motor"/>
    <joint name="RARM_JOINT1"/>
    <mechanicalReduction>1</mechanicalReduction>
  </transmission>
  <gazebo reference="RARM_JOINT1">
    <cfmDamping>0.4</cfmDamping>
  </gazebo>
  <joint name="RARM_JOINT2" type="revolute">
    <parent link="RARM_LINK1"/>
    <child link="RARM_LINK2"/>
    <origin rpy="0 -0 0 " xyz="0 -0.057 0"/>
    <axis xyz="1 0 0"/>
    <limit effort="287.171" lower="-3.14159" upper="-0.2762" velocity="4"/>
    <dynamics damping="0.2" friction="0"/>
  </joint>
  <transmission name="RARM_JOINT2_trans" type="pr2_mechanism_model/SimpleTransmission">
    <actuator name="RARM_JOINT2_motor"/>
    <joint name="RARM_JOINT2"/>
    <mechanicalReduction>1</mechanicalReduction>
  </transmission>
  <gazebo reference="RARM_JOINT2">
    <cfmDamping>0.4</cfmDamping>
  </gazebo>
  <joint name="RARM_JOINT3" type="revolute">
    <parent link="RARM_LINK2"/>
    <child link="RARM_LINK3"/>
    <origin rpy="0 -0 0 " xyz="0 0 -0.1965"/>
    <axis xyz="0 0 1"/>
    <limit effort="287.171" lower="-3.14159" upper="3.14159" velocity="4"/>
    <dynamics damping="0.2" friction="0"/>
  </joint>
  <transmission name="RARM_JOINT3_trans" type="pr2_mechanism_model/SimpleTransmission">
    <actuator name="RARM_JOINT3_motor"/>
    <joint name="RARM_JOINT3"/>
    <mechanicalReduction>1</mechanicalReduction>
  </transmission>
  <gazebo reference="RARM_JOINT3">
    <cfmDamping>0.4</cfmDamping>
  </gazebo>
  <joint name="RARM_JOINT4" type="revolute">
    <parent link="RARM_LINK3"/>
    <child link="RARM_LINK4"/>
    <origin rpy="0 -0 0 " xyz="0 0 -0.126"/>
    <axis xyz="0 1 0"/>
    <limit effort="287.171" lower="-2.19006" upper="1.0472" velocity="4"/>
    <dynamics damping="0.2" friction="0"/>
  </joint>
  <transmission name="RARM_JOINT4_trans" type="pr2_mechanism_model/SimpleTransmission">
    <actuator name="RARM_JOINT4_motor"/>
    <joint name="RARM_JOINT4"/>
    <mechanicalReduction>1</mechanicalReduction>
  </transmission>
  <gazebo reference="RARM_JOINT4">
    <cfmDamping>0.4</cfmDamping>
  </gazebo>
  <joint name="RARM_JOINT5" type="revolute">
    <parent link="RARM_LINK4"/>
    <child link="RARM_LINK5"/>
    <origin rpy="0 -0 0 " xyz="0 0 -0.1275"/>
    <axis xyz="0 0 1"/>
    <limit effort="287.171" lower="-3.14159" upper="3.14159" velocity="4"/>
    <dynamics damping="0.2" friction="0"/>
  </joint>
  <transmission name="RARM_JOINT5_trans" type="pr2_mechanism_model/SimpleTransmission">
    <actuator name="RARM_JOINT5_motor"/>
    <joint name="RARM_JOINT5"/>
    <mechanicalReduction>1</mechanicalReduction>
  </transmission>
  <gazebo reference="RARM_JOINT5">
    <cfmDamping>0.4</cfmDamping>
  </gazebo>
  <joint name="RARM_JOINT6" type="revolute">
    <parent link="RARM_LINK5"/>
    <child link="RARM_LINK6"/>
    <origin rpy="0 -0 0 " xyz="0 0 -0.146"/>
    <axis xyz="1 0 0"/>
    <limit effort="287.171" lower="-1.5708" upper="1.54494" velocity="4"/>
    <dynamics damping="0.2" friction="0"/>
  </joint>
  <transmission name="RARM_JOINT6_trans" type="pr2_mechanism_model/SimpleTransmission">
    <actuator name="RARM_JOINT6_motor"/>
    <joint name="RARM_JOINT6"/>
    <mechanicalReduction>1</mechanicalReduction>
  </transmission>
  <gazebo reference="RARM_JOINT6">
    <cfmDamping>0.4</cfmDamping>
  </gazebo>
  <joint name="RARM_JOINT7" type="revolute">
    <parent link="RARM_LINK6"/>
    <child link="RARM_LINK7"/>
    <origin rpy="0 -0 0 " xyz="0 0 -0.04"/>
    <axis xyz="0 1 0"/>
    <limit effort="288.965" lower="-1.41372" upper="1.0472" velocity="4"/>
    <dynamics damping="0.2" friction="0"/>
  </joint>
  <transmission name="RARM_JOINT7_trans" type="pr2_mechanism_model/SimpleTransmission">
    <actuator name="RARM_JOINT7_motor"/>
    <joint name="RARM_JOINT7"/>
    <mechanicalReduction>1</mechanicalReduction>
  </transmission>
  <gazebo reference="RARM_JOINT7">
    <cfmDamping>0.4</cfmDamping>
  </gazebo>
  <joint name="LLEG_JOINT0" type="revolute">
    <parent link="BODY"/>
    <child link="LLEG_LINK0"/>
    <origin rpy="0 -0 0 " xyz="0 0.1 0.0095"/>
    <axis xyz="0 0 1"/>
    <limit effort="339.972" lower="-1.0972" upper="1.02662" velocity="9"/>
    <dynamics damping="0.2" friction="0"/>
  </joint>
  <transmission name="LLEG_JOINT0_trans" type="pr2_mechanism_model/SimpleTransmission">
    <actuator name="LLEG_JOINT0_motor"/>
    <joint name="LLEG_JOINT0"/>
    <mechanicalReduction>1</mechanicalReduction>
  </transmission>
  <gazebo reference="LLEG_JOINT0">
    <cfmDamping>0.4</cfmDamping>
  </gazebo>
  <joint name="LLEG_JOINT1" type="revolute">
    <parent link="LLEG_LINK0"/>
    <child link="LLEG_LINK1"/>
    <origin rpy="0 -0 0 " xyz="0 0 -0.122"/>
    <axis xyz="1 0 0"/>
    <limit effort="543.955" lower="-0.523599" upper="0.725029" velocity="9"/>
    <dynamics damping="0.2" friction="0"/>
  </joint>
  <transmission name="LLEG_JOINT1_trans" type="pr2_mechanism_model/SimpleTransmission">
    <actuator name="LLEG_JOINT1_motor"/>
    <joint name="LLEG_JOINT1"/>
    <mechanicalReduction>1</mechanicalReduction>
  </transmission>
  <gazebo reference="LLEG_JOINT1">
    <cfmDamping>0.4</cfmDamping>
  </gazebo>
  <joint name="LLEG_JOINT2" type="revolute">
    <parent link="LLEG_LINK1"/>
    <child link="LLEG_LINK2"/>
    <origin rpy="0 -0 0 " xyz="0 0 -0.01"/>
    <axis xyz="0 1 0"/>
    <limit effort="679.944" lower="-2.11843" upper="0.785398" velocity="9"/>
    <dynamics damping="0.2" friction="0"/>
  </joint>
  <transmission name="LLEG_JOINT2_trans" type="pr2_mechanism_model/SimpleTransmission">
    <actuator name="LLEG_JOINT2_motor"/>
    <joint name="LLEG_JOINT2"/>
    <mechanicalReduction>1</mechanicalReduction>
  </transmission>
  <gazebo reference="LLEG_JOINT2">
    <cfmDamping>0.4</cfmDamping>
  </gazebo>
  <joint name="LLEG_JOINT3" type="revolute">
    <parent link="LLEG_LINK2"/>
    <child link="LLEG_LINK3"/>
    <origin rpy="0 -0 0 " xyz="0 0 -0.38"/>
    <axis xyz="0 1 0"/>
    <limit effort="679.944" lower="0" upper="2.77419" velocity="9"/>
    <dynamics damping="0.2" friction="0"/>
  </joint>
  <transmission name="LLEG_JOINT3_trans" type="pr2_mechanism_model/SimpleTransmission">
    <actuator name="LLEG_JOINT3_motor"/>
    <joint name="LLEG_JOINT3"/>
    <mechanicalReduction>1</mechanicalReduction>
  </transmission>
  <gazebo reference="LLEG_JOINT3">
    <cfmDamping>0.4</cfmDamping>
  </gazebo>
  <joint name="LLEG_JOINT4" type="revolute">
    <parent link="LLEG_LINK3"/>
    <child link="LLEG_LINK4"/>
    <origin rpy="0 -0 0 " xyz="0 0 -0.38"/>
    <axis xyz="0 1 0"/>
    <limit effort="407.966" lower="-1.38564" upper="1.47343" velocity="9"/>
    <dynamics damping="0.2" friction="0"/>
  </joint>
  <transmission name="LLEG_JOINT4_trans" type="pr2_mechanism_model/SimpleTransmission">
    <actuator name="LLEG_JOINT4_motor"/>
    <joint name="LLEG_JOINT4"/>
    <mechanicalReduction>1</mechanicalReduction>
  </transmission>
  <gazebo reference="LLEG_JOINT4">
    <cfmDamping>0.4</cfmDamping>
  </gazebo>
  <joint name="LLEG_JOINT5" type="revolute">
    <parent link="LLEG_LINK4"/>
    <child link="LLEG_LINK5"/>
    <origin rpy="0 -0 0 " xyz="0 0 -0.04"/>
    <axis xyz="1 0 0"/>
    <limit effort="342.097" lower="-1.0472" upper="1.0472" velocity="9"/>
    <dynamics damping="0.2" friction="0"/>
  </joint>
  <transmission name="LLEG_JOINT5_trans" type="pr2_mechanism_model/SimpleTransmission">
    <actuator name="LLEG_JOINT5_motor"/>
    <joint name="LLEG_JOINT5"/>
    <mechanicalReduction>1</mechanicalReduction>
  </transmission>
  <gazebo reference="LLEG_JOINT5">
    <cfmDamping>0.4</cfmDamping>
  </gazebo>
  <joint name="RLEG_JOINT0" type="revolute">
    <parent link="BODY"/>
    <child link="RLEG_LINK0"/>
    <origin rpy="0 -0 0 " xyz="0 -0.1 0.0095"/>
    <axis xyz="0 0 1"/>
    <limit effort="339.972" lower="-1.02662" upper="1.0972" velocity="9"/>
    <dynamics damping="0.2" friction="0"/>
  </joint>
  <transmission name="RLEG_JOINT0_trans" type="pr2_mechanism_model/SimpleTransmission">
    <actuator name="RLEG_JOINT0_motor"/>
    <joint name="RLEG_JOINT0"/>
    <mechanicalReduction>1</mechanicalReduction>
  </transmission>
  <gazebo reference="RLEG_JOINT0">
    <cfmDamping>0.4</cfmDamping>
  </gazebo>
  <joint name="RLEG_JOINT1" type="revolute">
    <parent link="RLEG_LINK0"/>
    <child link="RLEG_LINK1"/>
    <origin rpy="0 -0 0 " xyz="0 0 -0.122"/>
    <axis xyz="1 0 0"/>
    <limit effort="543.955" lower="-0.725029" upper="0.523599" velocity="9"/>
    <dynamics damping="0.2" friction="0"/>
  </joint>
  <transmission name="RLEG_JOINT1_trans" type="pr2_mechanism_model/SimpleTransmission">
    <actuator name="RLEG_JOINT1_motor"/>
    <joint name="RLEG_JOINT1"/>
    <mechanicalReduction>1</mechanicalReduction>
  </transmission>
  <gazebo reference="RLEG_JOINT1">
    <cfmDamping>0.4</cfmDamping>
  </gazebo>
  <joint name="RLEG_JOINT2" type="revolute">
    <parent link="RLEG_LINK1"/>
    <child link="RLEG_LINK2"/>
    <origin rpy="0 -0 0 " xyz="0 0 -0.01"/>
    <axis xyz="0 1 0"/>
    <limit effort="679.944" lower="-2.11843" upper="0.785398" velocity="9"/>
    <dynamics damping="0.2" friction="0"/>
  </joint>
  <transmission name="RLEG_JOINT2_trans" type="pr2_mechanism_model/SimpleTransmission">
    <actuator name="RLEG_JOINT2_motor"/>
    <joint name="RLEG_JOINT2"/>
    <mechanicalReduction>1</mechanicalReduction>
  </transmission>
  <gazebo reference="RLEG_JOINT2">
    <cfmDamping>0.4</cfmDamping>
  </gazebo>
  <joint name="RLEG_JOINT3" type="revolute">
    <parent link="RLEG_LINK2"/>
    <child link="RLEG_LINK3"/>
    <origin rpy="0 -0 0 " xyz="0 0 -0.38"/>
    <axis xyz="0 1 0"/>
    <limit effort="679.944" lower="0" upper="2.77419" velocity="9"/>
    <dynamics damping="0.2" friction="0"/>
  </joint>
  <transmission name="RLEG_JOINT3_trans" type="pr2_mechanism_model/SimpleTransmission">
    <actuator name="RLEG_JOINT3_motor"/>
    <joint name="RLEG_JOINT3"/>
    <mechanicalReduction>1</mechanicalReduction>
  </transmission>
  <gazebo reference="RLEG_JOINT3">
    <cfmDamping>0.4</cfmDamping>
  </gazebo>
  <joint name="RLEG_JOINT4" type="revolute">
    <parent link="RLEG_LINK3"/>
    <child link="RLEG_LINK4"/>
    <origin rpy="0 -0 0 " xyz="0 0 -0.38"/>
    <axis xyz="0 1 0"/>
    <limit effort="407.966" lower="-1.38564" upper="1.47343" velocity="9"/>
    <dynamics damping="0.2" friction="0"/>
  </joint>
  <transmission name="RLEG_JOINT4_trans" type="pr2_mechanism_model/SimpleTransmission">
    <actuator name="RLEG_JOINT4_motor"/>
    <joint name="RLEG_JOINT4"/>
    <mechanicalReduction>1</mechanicalReduction>
  </transmission>
  <gazebo reference="RLEG_JOINT4">
    <cfmDamping>0.4</cfmDamping>
  </gazebo>
  <joint name="RLEG_JOINT5" type="revolute">
    <parent link="RLEG_LINK4"/>
    <child link="RLEG_LINK5"/>
    <origin rpy="0 -0 0 " xyz="0 0 -0.04"/>
    <axis xyz="1 0 0"/>
    <limit effort="342.097" lower="-1.0472" upper="1.0472" velocity="9"/>
    <dynamics damping="0.2" friction="0"/>
  </joint>
  <transmission name="RLEG_JOINT5_trans" type="pr2_mechanism_model/SimpleTransmission">
    <actuator name="RLEG_JOINT5_motor"/>
    <joint name="RLEG_JOINT5"/>
    <mechanicalReduction>1</mechanicalReduction>
  </transmission>
  <gazebo reference="RLEG_JOINT5">
    <cfmDamping>0.4</cfmDamping>
  </gazebo>
  <!-- -->
  <link name="LARM_LINK7">
    <visual>
      <origin rpy="0 -0 0" xyz="0 0.0 0"/>
      <geometry>
	<mesh filename="package://hrpsys_ros_bridge_tutorials/models/JAXON_meshes/l_hand_attached_link.dae" scale="1 1 1"/>
      </geometry>
    </visual>
    <collision>
      <origin rpy="0 -0 0" xyz="0 0.0 0"/>
      <geometry>
	<mesh filename="package://hrpsys_ros_bridge_tutorials/models/JAXON_meshes/l_hand_attached_link.dae" scale="1 1 1"/>
      </geometry>
    </collision>
    <inertial>
      <!-- mass propaties should be corrected -->
      <mass value="4.219"/>
      <origin rpy="0 -0 0" xyz="-0.02359 0.12884 -0.02825"/>
      <inertia ixx="0.0527968" ixy="0" ixz="0" iyy="0.057042" iyz="0" izz="0.0492541"/>
    </inertial>
  </link>
  <gazebo reference="LARM_LINK7">
    <mu1>0.9</mu1>
    <mu2>0.9</mu2>
  </gazebo>
  <!-- -->
  <link name="RARM_LINK7">
    <visual>
      <origin rpy="0 -0 0" xyz="0 0 0"/>
      <geometry>
	<mesh filename="package://hrpsys_ros_bridge_tutorials/models/JAXON_meshes/r_hand_attached_link.dae" scale="1 1 1"/>
      </geometry>
    </visual>
    <collision>
      <origin rpy="0 -0 0" xyz="0 0 0"/>
      <geometry>
	<mesh filename="package://hrpsys_ros_bridge_tutorials/models/JAXON_meshes/r_hand_attached_link.dae" scale="1 1 1"/>
      </geometry>
    </collision>
    <inertial>
      <!-- mass propaties should be corrected -->
      <mass value="4.219"/>
      <origin rpy="0 -0 0" xyz="0.02359 -0.12884 -0.02825"/>
      <inertia ixx="0.0527968" ixy="0" ixz="0" iyy="0.057042" iyz="0" izz="0.0492541"/>
    </inertial>
  </link>
  <gazebo reference="RARM_LINK7">
    <mu1>0.9</mu1>
    <mu2>0.9</mu2>
  </gazebo>
  <!-- HEAD -->
  <!-- Head Link Simplified Collision Mesh -->
  <link name="head_root"/>
  <joint name="head_root_joint" type="fixed">
    <parent link="head_root"/>
    <child link="head"/>
  </joint>
  <link name="head">
    <inertial>
      <origin rpy="0 0 0" xyz="-0.075493 3.3383E-05 0.02774"/>
      <mass value="1.4199"/>
      <inertia ixx="0.0039688" ixy="-1.5797E-06" ixz="-0.00089293" iyy="0.0041178" iyz="-6.8415E-07" izz="0.0035243"/>
    </inertial>
    <visual>
      <origin rpy="0 0 0" xyz="0 0  0"/>
      <geometry>
	<mesh filename="package://multisense_description/meshes/head.dae"/>
      </geometry>
      <material name="">
	<color rgba="0.9098 0.44314 0.031373 1"/>
      </material>
    </visual>
    <collision>
      <origin rpy="0 0 0" xyz="-0.0503 0 -0.00195"/>
      <geometry>
	<box size="0.1311 0.12 0.0591"/>
      </geometry>
    </collision>
  </link>
  <!-- <link name="hokuyo_link"> -->
  <!-- 	<inertial> -->
  <!-- 		<origin rpy="0 0 0" xyz="0.012428 0.0004084 -0.0041835"/> -->
  <!-- 		<mass value="0.057664"/> -->
  <!-- 		<inertia ixx="3.7174E-05" ixy="4.9927E-08" ixz="1.1015E-05" iyy="4.2412E-05" iyz="-9.8165E-09" izz="4.167E-05"/> -->
  <!-- 	</inertial> -->
  <!-- 	<visual> -->
  <!-- 		<origin rpy="-1.9179632679 -1.57079632679 0" xyz="-.03 -.1 0"/> -->
  <!-- 		<geometry> -->
  <!-- 			<mesh filename="package://multisense_description/meshes/head_camera.dae"/> -->
  <!-- 		</geometry> -->
  <!-- 		<material name=""> -->
  <!-- 			<color rgba="0.72941 0.35686 0.023529 1"/> -->
  <!-- 		</material> -->
  <!-- 	</visual> -->
  <!-- 	<collision> -->
  <!-- 		<origin rpy="0 0 0" xyz="0.03 0 0.0235"/> -->
  <!-- 		<geometry> -->
  <!-- 			<cylinder length="0.047" radius="0.024425"/> -->
  <!-- 		</geometry> -->
  <!-- 	</collision> -->
  <!-- </link> -->
  <!-- <link name="head_hokuyo_frame"/> -->
  <!-- <joint name="head_hokuyo_frame_joint" type="fixed"> -->
  <!--
      This transform accounts for the fact ROS expects laser data in the x forward,
      y left, z up frame and the calibraton has the data in x left, y up, z forward.
      Thus a roll of -90 * a pitch of -90 will make the appropriate transform. Note
      Roll and pitch are both with respect to the origional x left, y up, z forward frame
  -->
  <!-- 	<origin rpy="-1.57079632679 -1.57079632679 0.0" xyz="0 0 0"/> -->
  <!-- 	<parent link="hokuyo_link"/> -->
  <!-- 	<child link="head_hokuyo_frame"/> -->
  <!-- </joint> -->
  <!-- Stereo Camera -->
  <joint name="left_camera_frame_joint" type="fixed">
    <!-- optical frame collocated with tilting DOF -->
    <origin xyz="0.0 0.035 -0.002"/>
    <parent link="head"/>
    <child link="left_camera_frame"/>
  </joint>
  <link name="left_camera_frame">
    <inertial>
      <mass value="0.1"/>
      <origin xyz="0 0 0"/>
      <inertia ixx="0.001" ixy="0.0" ixz="0.0" iyy="0.001" iyz="0.0" izz="0.001"/>
    </inertial>
  </link>
  <joint name="left_camera_optical_frame_joint" type="fixed">
    <origin rpy="-1.57079632679 0.0 -1.57079632679" xyz="0 0 0"/>
    <parent link="left_camera_frame"/>
    <child link="left_camera_optical_frame"/>
  </joint>
  <joint name="right_camera_frame_joint" type="fixed">
    <origin xyz="0.0 -0.035 -0.002"/>
    <parent link="head"/>
    <child link="right_camera_frame"/>
  </joint>
  <link name="right_camera_frame">
    <inertial>
      <mass value="0.1"/>
      <origin xyz="0 0 0"/>
      <inertia ixx="0.001" ixy="0.0" ixz="0.0" iyy="0.001" iyz="0.0" izz="0.001"/>
    </inertial>
  </link>
  <joint name="right_camera_optical_frame_joint" type="fixed">
    <origin rpy="-1.5708 0.0 -1.5708" xyz="0 0 0"/>
    <parent link="right_camera_frame"/>
    <child link="right_camera_optical_frame"/>
  </joint>
  <link name="right_camera_optical_frame"/>
  <joint name="center_top_led_frame_joint" type="fixed">
    <origin xyz="0.01125 0.0 0.0105"/>
    <parent link="head"/>
    <child link="center_top_led_frame"/>
  </joint>
  <link name="center_top_led_frame">
    <inertial>
      <mass value="0.1"/>
      <origin xyz="0 0 0"/>
      <inertia ixx="0.001" ixy="0.0" ixz="0.0" iyy="0.001" iyz="0.0" izz="0.001"/>
    </inertial>
  </link>
  <joint name="center_bottom_led_frame_joint" type="fixed">
    <origin xyz="0.01125 0.0 -0.0155"/>
    <parent link="head"/>
    <child link="center_bottom_led_frame"/>
  </joint>
  <link name="center_bottom_led_frame">
    <inertial>
      <mass value="0.1"/>
      <origin xyz="0 0 0"/>
      <inertia ixx="0.001" ixy="0.0" ixz="0.0" iyy="0.001" iyz="0.0" izz="0.001"/>
    </inertial>
  </link>
  <joint name="left_led_frame_joint" type="fixed">
    <origin rpy="0 -0.15 0.53" xyz="-0.01443 0.07452 0.050346"/>
    <parent link="head"/>
    <child link="left_led_frame"/>
  </joint>
  <link name="left_led_frame">
    <inertial>
      <mass value="0.1"/>
      <origin xyz="0 0 0"/>
      <inertia ixx="0.001" ixy="0.0" ixz="0.0" iyy="0.001" iyz="0.0" izz="0.001"/>
    </inertial>
  </link>
  <joint name="right_led_frame_joint" type="fixed">
    <origin rpy="0 -0.15 -0.53" xyz="-0.01443 -0.07452 0.050346"/>
    <parent link="head"/>
    <child link="right_led_frame"/>
  </joint>
  <link name="right_led_frame">
    <inertial>
      <mass value="0.1"/>
      <origin xyz="0 0 0"/>
      <inertia ixx="0.001" ixy="0.0" ixz="0.0" iyy="0.001" iyz="0.0" izz="0.001"/>
    </inertial>
  </link>
  <!-- IMU Frames, Mag/Accel and Gyro -->
  <!-- Include transfrom to the left_camera_frame (shift in -.035mm in X and -.002mm in Z) -->
  <link name="accel"/>
  <joint name="accel_joint" type="fixed">
    <origin rpy="0 1.5707 0" xyz="-.0475 .0302 -.00275"/>
    <parent link="head_root"/>
    <child link="accel"/>
  </joint>
  <link name="mag"/>
  <joint name="mag_joint" type="fixed">
    <origin rpy="0 1.5707 0" xyz="-.0475 .0302 -.00275"/>
    <parent link="head_root"/>
    <child link="mag"/>
  </joint>
  <link name="gyro"/>
  <joint name="gyro_joint" type="fixed">
    <origin rpy="1.5707 3.14159 1.5707 " xyz="-.0476 .0388 -.00075"/>
    <parent link="head_root"/>
    <child link="gyro"/>
  </joint>
  <joint name="head_tip_to_multisense" type="fixed">
    <parent link="HEAD_LINK1"/>
    <child link="head_root"/>
    <!-- <origin rpy="-0.01 0.01 0.017" xyz="0.08 0.01 0.045"/> -->
    <!-- For leg -->
    <!-- <rigin rpy="-0.01 0.02 0.017" xyz="0.07 -0.01 0.045"/> old -->
    <!-- <origin rpy="-0.01 0.01 0.017" xyz="0.09 0.01 0.055"/>  -->
    <!--middle-->
    <!-- <origin rpy="-0.01 0.01 0.017" xyz="0.10 0.01 0.065"/> -->
    <!-- For hand -->
    <!-- <origin rpy="-0.01 0.035 -0.005" xyz="0.085 0.01 0.065"/> -->
    <!-- old head in 20151022 -->
    <!-- <origin rpy="-0.004 0.275 -0.01" xyz="0.1 0.01 0.085"/> -->
    <!-- new head in 20151022 -->
    <!-- <origin rpy="0.003 0.255 -0.02" xyz="0.1 0.01 0.085"/> -->
    <!-- new head in 20151125 -->
    <origin rpy="0.015 0.035 -0.02" xyz="0.085 0.01 0.085"/>
    <!-- revert to old head in 20151127 -->
  </joint>
  <!-- HAND -->
  <!-- inertial parameter is not correct -->
  <link name="L_thk_palm">
    <inertial>
      <origin rpy="0 0 0" xyz="0.0835 0 -0.0181"/>
      <mass value="0.8"/>
      <inertia ixx="0.001314416" ixy="0" ixz="0" iyy="0.002746271" iyz="0" izz="0.002284148"/>
    </inertial>
    <visual>
      <geometry>
	<mesh filename="package://jaxon_description/hand_meshes/THK_003_palm.stl"/>
      </geometry>
      <material name="blue">
	<color rgba="0.0 0.0 0.8 1.0"/>
      </material>
    </visual>
    <collision>
      <origin rpy="0 0 0" xyz="0.054 0 0"/>
      <geometry>
	<mesh filename="package://jaxon_description/hand_meshes/THK_003_palm.stl"/>
      </geometry>
    </collision>
  </link>
  <link name="L_thk_finger1">
    <inertial>
      <origin rpy="0 0 0" xyz="0.021 0 -0.04556"/>
      <mass value="0.2"/>
      <inertia ixx="2.980527e-04" ixy="0" ixz="0" iyy="3.552534e-04" iyz="0" izz="7.05341e-5"/>
    </inertial>
    <visual>
      <origin rpy="0 0 0" xyz="0.0 0 0"/>
      <geometry>
	<mesh filename="package://jaxon_description/hand_meshes/THK_003_finger1.stl"/>
      </geometry>
      <material name="blue"/>
    </visual>
    <collision>
      <origin rpy="0 0 0" xyz="0.0 0 0"/>
      <geometry>
	<mesh filename="package://jaxon_description/hand_meshes/THK_003_finger1.stl"/>
      </geometry>
    </collision>
  </link>
  <link name="L_thk_finger2">
    <inertial>
      <origin rpy="0 0 0" xyz="0.0577 0 -0.0151"/>
      <mass value="0.4"/>
      <inertia ixx="3.570504e-04" ixy="0" ixz="0" iyy="8.546976e-04" iyz="0" izz="8.168899e-04"/>
    </inertial>
    <visual>
      <origin rpy="0 0 0" xyz="0 0 0"/>
      <geometry>
	<mesh filename="package://jaxon_description/hand_meshes/THK_003_finger2.stl"/>
      </geometry>
      <material name="blue"/>
    </visual>
    <collision>
      <origin rpy="0 0 0" xyz="0 0 0"/>
      <geometry>
	<mesh filename="package://jaxon_description/hand_meshes/THK_003_finger2.stl"/>
      </geometry>
    </collision>
  </link>
  <joint name="L_thk_finger1_joint" type="revolute">
    <origin rpy="0 0 0" xyz="0.089 0 -0.055"/>
    <parent link="L_thk_palm"/>
    <child link="L_thk_finger1"/>
    <axis xyz="0 1 0"/>
    <limit effort="20" lower="-1.6" upper="0" velocity="4"/>
  </joint>
  <joint name="L_thk_finger2_joint" type="revolute">
    <origin rpy="0 0 0" xyz="0.089 0 0.055"/>
    <parent link="L_thk_palm"/>
    <child link="L_thk_finger2"/>
    <axis xyz="0 1 0"/>
    <limit effort="20" lower="0" upper="1.6" velocity="4"/>
  </joint>
  <joint name="L_thk_palm" type="fixed">
    <origin rpy="-1.5707963268 1.5707963268 0" xyz="0 0 -0.085"/>
    <parent link="LARM_LINK7"/>
    <child link="L_thk_palm"/>
  </joint>
  <link name="R_thk_palm">
    <inertial>
      <origin rpy="0 0 0" xyz="0.0835 0 -0.0181"/>
      <mass value="0.8"/>
      <inertia ixx="0.001314416" ixy="0" ixz="0" iyy="0.002746271" iyz="0" izz="0.002284148"/>
    </inertial>
    <visual>
      <geometry>
	<mesh filename="package://jaxon_description/hand_meshes/THK_003_palm.stl"/>
      </geometry>
      <material name="blue">
	<color rgba="0.0 0.0 0.8 1.0"/>
      </material>
    </visual>
    <collision>
      <origin rpy="0 0 0" xyz="0.054 0 0"/>
      <geometry>
	<mesh filename="package://jaxon_description/hand_meshes/THK_003_palm.stl"/>
      </geometry>
    </collision>
  </link>
  <link name="R_thk_finger1">
    <inertial>
      <origin rpy="0 0 0" xyz="0.021 0 -0.04556"/>
      <mass value="0.2"/>
      <inertia ixx="2.980527e-04" ixy="0" ixz="0" iyy="3.552534e-04" iyz="0" izz="7.05341e-5"/>
    </inertial>
    <visual>
      <origin rpy="0 0 0" xyz="0.0 0 0"/>
      <geometry>
	<mesh filename="package://jaxon_description/hand_meshes/THK_003_finger1.stl"/>
      </geometry>
      <material name="blue"/>
    </visual>
    <collision>
      <origin rpy="0 0 0" xyz="0.0 0 0"/>
      <geometry>
	<mesh filename="package://jaxon_description/hand_meshes/THK_003_finger1.stl"/>
      </geometry>
    </collision>
  </link>
  <link name="R_thk_finger2">
    <inertial>
      <origin rpy="0 0 0" xyz="0.0577 0 -0.0151"/>
      <mass value="0.4"/>
      <inertia ixx="3.570504e-04" ixy="0" ixz="0" iyy="8.546976e-04" iyz="0" izz="8.168899e-04"/>
    </inertial>
    <visual>
      <origin rpy="0 0 0" xyz="0 0 0"/>
      <geometry>
	<mesh filename="package://jaxon_description/hand_meshes/THK_003_finger2.stl"/>
      </geometry>
      <material name="blue"/>
    </visual>
    <collision>
      <origin rpy="0 0 0" xyz="0 0 0"/>
      <geometry>
	<mesh filename="package://jaxon_description/hand_meshes/THK_003_finger2.stl"/>
      </geometry>
    </collision>
  </link>
  <joint name="R_thk_finger1_joint" type="revolute">
    <origin rpy="0 0 0" xyz="0.089 0 -0.055"/>
    <parent link="R_thk_palm"/>
    <child link="R_thk_finger1"/>
    <axis xyz="0 1 0"/>
    <limit effort="20" lower="-1.6" upper="0" velocity="4"/>
  </joint>
  <joint name="R_thk_finger2_joint" type="revolute">
    <origin rpy="0 0 0" xyz="0.089 0 0.055"/>
    <parent link="R_thk_palm"/>
    <child link="R_thk_finger2"/>
    <axis xyz="0 1 0"/>
    <limit effort="20" lower="0" upper="1.6" velocity="4"/>
  </joint>
  <joint name="R_thk_palm" type="fixed">
    <origin rpy="1.5707963268 1.5707963268 0" xyz="0 0 -0.085"/>
    <parent link="RARM_LINK7"/>
    <child link="R_thk_palm"/>
  </joint>
  <joint name="rfsensor_joint" type="fixed">
    <origin rpy="3.141593 0.000000 3.141593" xyz="0 0 -0.069"/>
    <parent link="RLEG_LINK5"/>
    <child link="rfsensor"/>
  </joint>
  <link name="rfsensor"/>
  <joint name="lfsensor_joint" type="fixed">
    <origin rpy="3.141593 0.000000 3.141593" xyz="0 0 -0.069"/>
    <parent link="LLEG_LINK5"/>
    <child link="lfsensor"/>
  </joint>
  <link name="lfsensor"/>
  <joint name="rhsensor_joint" type="fixed">
    <origin rpy="-3.141593 -0.000000 2.356196" xyz="0 0 -0.069"/>
    <parent link="RARM_LINK7"/>
    <child link="rhsensor"/>
  </joint>
  <link name="rhsensor"/>
  <joint name="lhsensor_joint" type="fixed">
    <origin rpy="3.141593 -0.000000 -2.356196" xyz="0 0 -0.069"/>
    <parent link="LARM_LINK7"/>
    <child link="lhsensor"/>
  </joint>
  <link name="lhsensor"/>
  <joint name="fisheye_joint" type="fixed">
    <origin rpy="3.141593 -0.523599 0.000000" xyz="0.147 0 -0.022"/>
    <parent link="CHEST_LINK2"/>
    <child link="fisheye"/>
  </joint>
  <link name="fisheye"/>
  <joint name="rleg_end_coords_joint" type="fixed">
    <origin rpy="0.000000 -0.000000 0.000000" xyz="0 0 -0.11"/>
    <parent link="RLEG_LINK5"/>
    <child link="rleg_end_coords"/>
  </joint>
  <link name="rleg_end_coords"/>
  <joint name="lleg_end_coords_joint" type="fixed">
    <origin rpy="0.000000 -0.000000 0.000000" xyz="0 0 -0.11"/>
    <parent link="LLEG_LINK5"/>
    <child link="lleg_end_coords"/>
  </joint>
  <link name="lleg_end_coords"/>
  <joint name="rarm_end_coords_joint" type="fixed">
    <origin rpy="-0.000000 1.570796 0.000000" xyz="0 0 -0.22"/>
    <parent link="RARM_LINK7"/>
    <child link="rarm_end_coords"/>
  </joint>
  <link name="rarm_end_coords"/>
  <joint name="larm_end_coords_joint" type="fixed">
    <origin rpy="-0.000000 1.570796 0.000000" xyz="0 0 -0.22"/>
    <parent link="LARM_LINK7"/>
    <child link="larm_end_coords"/>
  </joint>
  <link name="larm_end_coords"/>
  <joint name="head_end_coords_joint" type="fixed">
    <origin rpy="-0.000000 1.570796 0.000000" xyz="0.1 0.0 0.1"/>
    <parent link="HEAD_LINK1"/>
    <child link="head_end_coords"/>
  </joint>
  <link name="head_end_coords"/>
  <gazebo reference="LLEG_LINK5">
    <kp>1000000.0</kp>
    <kd>100.0</kd>
    <mu1>1.5</mu1>
    <mu2>1.5</mu2>
    <fdir1>1 0 0</fdir1>
    <maxVel>10.0</maxVel>
    <minDepth>0.00</minDepth>
  </gazebo>
  <gazebo reference="RLEG_LINK5">
    <kp>1000000.0</kp>
    <kd>100.0</kd>
    <mu1>1.5</mu1>
    <mu2>1.5</mu2>
    <fdir1>1 0 0</fdir1>
    <maxVel>10.0</maxVel>
    <minDepth>0.00</minDepth>
  </gazebo>
  <link name="left_camera_optical_frame">
    <inertial>
      <mass value="0.1"/>
      <origin xyz="0 0 0"/>
      <inertia ixx="0.001" ixy="0.0" ixz="0.0" iyy="0.001" iyz="0.0" izz="0.001"/>
    </inertial>
  </link>
  <!-- <link name="motor"> -->
  <!-- 	<inertial> -->
  <!-- 		<mass value="0.1"/> -->
  <!-- 		<origin xyz="0 0 0"/> -->
  <!-- 		<inertia ixx="0.001" ixy="0.0" ixz="0.0" iyy="0.001" iyz="0.0" izz="0.001"/> -->
  <!-- 	</inertial> -->
  <!-- </link> -->
  <!-- <link name="spindle"> -->
  <!-- 	<inertial> -->
  <!-- 		<mass value="0.1"/> -->
  <!-- 		<origin xyz="0 0 0"/> -->
  <!-- 		<inertia ixx="0.001" ixy="0.0" ixz="0.0" iyy="0.001" iyz="0.0" izz="0.001"/> -->
  <!-- 	</inertial> -->
  <!-- </link> -->
  <joint name="left_camera_optical_joint" type="continuous">
    <parent link="left_camera_optical_frame"/>
    <!-- <child link="motor"/> -->
    <origin rpy="0.009 -0.002 -1.044" xyz="0.031 -0.081 -0.002"/>
  </joint>
  <!-- <joint name="motor_joint" type="continuous"> -->
  <!-- 	<parent link="motor"/> -->
  <!-- 	<child link="spindle"/> -->
  <!-- 	<origin rpy="0.0 0.0 0.0" xyz="0.0 0.0 0.0"/> -->
  <!-- 	<axis xyz="0 0 1"/> -->
  <!-- </joint> -->
  <!-- <joint name="spindle_joint" type="continuous"> -->
  <!-- 	<parent link="spindle"/> -->
  <!-- 	<child link="hokuyo_link"/> -->
  <!-- 	<origin rpy="0.001 -0.012 -0.000" xyz="0.001 0.020 0.0"/> -->
  <!-- </joint> -->
</robot>
